<?xml version="1.0" ?>
<!-- =================================================================================== -->
<!-- |    This document was autogenerated by xacro from my_robot.urdf.xacro            | -->
<!-- |    EDITING THIS FILE BY HAND IS NOT RECOMMENDED                                 | -->
<!-- =================================================================================== -->
<robot name="my_robot">
  <material name="blue">
    <color rgba="0 0.5 0.5 1"/>
  </material>
  <material name="white">
    <color rgba="1 1 1 1"/>
  </material>
  <material name="red">
    <color rgba="1 0 0 1"/>
  </material>
  <link name="base_link">
    <visual>
      <geometry>
        <box size="0.6 0.4 0.2"/>
      </geometry>
      <material name="blue"/>
      <origin rpy="0 0 0" xyz="0 0 0.1"/>
    </visual>
    <collision>
      <geometry>
        <box size="0.6 0.4 0.2"/>
      </geometry>
      <origin rpy="0 0 0" xyz="0 0 0.1"/>
    </collision>
    <inertial>
      <origin rpy="0 0 0" xyz="0 0 0.1"/>
      <mass value="5.0"/>
      <inertia ixx="0.16666666666666669" ixy="0" ixz="0" iyy="0.08333333333333336" iyz="0" izz="0.21666666666666667"/>
    </inertial>
  </link>
  <link name="camera">
    <visual>
      <geometry>
        <box size="0.02 0.01 0.03"/>
      </geometry>
      <material name="red"/>
      <origin rpy="0 0 0" xyz="0 0 0"/>
    </visual>
    <collision>
      <geometry>
        <box size="0.02 0.01 0.03"/>
      </geometry>
      <material name="red"/>
      <origin rpy="0 0 0" xyz="0 0 0"/>
    </collision>
    <inertial>
      <origin rpy="0 0 0" xyz="0.3 0.2 0.1"/>
      <mass value="0.5"/>
      <inertia ixx="5.4166666666666664e-05" ixy="0" ixz="0" iyy="4.1666666666666665e-05" iyz="0" izz="2.0833333333333333e-05"/>
    </inertial>
  </link>
  <joint name="joint_cam" type="fixed">
    <parent link="base_link"/>
    <child link="camera"/>
    <origin rpy="0 0 0" xyz="0.3 0 0.1"/>
  </joint>
  <link name="lidar">
    <visual>
      <geometry>
        <cylinder length="0.1" radius="0.05"/>
      </geometry>
      <material name="white"/>
      <origin rpy="0 0 0" xyz="0.1 0 0.05"/>
    </visual>
    <collision>
      <geometry>
        <cylinder length="0.1" radius="0.05"/>
      </geometry>
      <origin rpy="0 0 0" xyz="0.1 0 0.05"/>
    </collision>
    <inertial>
      <origin rpy="0 0 0" xyz="0.1 0 0.05"/>
      <mass value="0.5"/>
      <inertia ixx="0.0007291666666666667" ixy="0" ixz="0" iyy="0.0007291666666666667" iyz="0" izz="0.0006250000000000001"/>
    </inertial>
  </link>
  <joint name="joint_1" type="fixed">
    <parent link="base_link"/>
    <child link="lidar"/>
    <origin rpy="0 0 0" xyz="0 0 0.2"/>
  </joint>
  <link name="wheel_right_1">
    <visual>
      <geometry>
        <cylinder length="0.05" radius="0.1"/>
      </geometry>
      <material name="white"/>
      <origin rpy="0 0 0" xyz="0 0 0.025"/>
    </visual>
    <collision>
      <geometry>
        <cylinder length="0.05" radius="0.1"/>
      </geometry>
      <origin rpy="0 0 0" xyz="0 0 0.025"/>
    </collision>
    <inertial>
      <origin rpy="0 0 0" xyz="0 0 0.025"/>
      <mass value="1.0"/>
      <inertia ixx="0.002708333333333334" ixy="0" ixz="0" iyy="0.002708333333333334" iyz="0" izz="0.005000000000000001"/>
    </inertial>
  </link>
  <joint name="joint_2" type="continuous">
    <parent link="base_link"/>
    <child link="wheel_right_1"/>
    <axis xyz="0 0 1"/>
    <origin rpy="1.57 0 0" xyz="0.2 -0.2 0.05"/>
  </joint>
  <link name="wheel_right_2">
    <visual>
      <geometry>
        <cylinder length="0.05" radius="0.1"/>
      </geometry>
      <material name="white"/>
      <origin rpy="0 0 0" xyz="0 0 0.025"/>
    </visual>
    <collision>
      <geometry>
        <cylinder length="0.05" radius="0.1"/>
      </geometry>
      <origin rpy="0 0 0" xyz="0 0 0.025"/>
    </collision>
    <inertial>
      <origin rpy="0 0 0" xyz="0 0 0.025"/>
      <mass value="1.0"/>
      <inertia ixx="0.002708333333333334" ixy="0" ixz="0" iyy="0.002708333333333334" iyz="0" izz="0.005000000000000001"/>
    </inertial>
  </link>
  <joint name="joint_3" type="continuous">
    <parent link="base_link"/>
    <child link="wheel_right_2"/>
    <axis xyz="0 0 1"/>
    <origin rpy="1.57 0 0" xyz="-0.2 -0.2 0.05"/>
  </joint>
  <link name="wheel_left_1">
    <visual>
      <geometry>
        <cylinder length="0.05" radius="0.1"/>
      </geometry>
      <material name="white"/>
      <origin rpy="0 0 0" xyz="0 0 -0.025"/>
    </visual>
    <collision>
      <geometry>
        <cylinder length="0.05" radius="0.1"/>
      </geometry>
      <origin rpy="0 0 0" xyz="0 0 -0.025"/>
    </collision>
    <inertial>
      <origin rpy="0 0 0" xyz="0 0 -0.025"/>
      <mass value="1.0"/>
      <inertia ixx="0.002708333333333334" ixy="0" ixz="0" iyy="0.002708333333333334" iyz="0" izz="0.005000000000000001"/>
    </inertial>
  </link>
  <joint name="joint_4" type="continuous">
    <parent link="base_link"/>
    <child link="wheel_left_1"/>
    <axis xyz="0 0 1"/>
    <origin rpy="1.57 0 0" xyz="0.2 0.2 0.05"/>
  </joint>
  <link name="wheel_left_2">
    <visual>
      <geometry>
        <cylinder length="0.05" radius="0.1"/>
      </geometry>
      <material name="white"/>
      <origin rpy="0 0 0" xyz="0 0 -0.025"/>
    </visual>
    <collision>
      <geometry>
        <cylinder length="0.05" radius="0.1"/>
      </geometry>
      <origin rpy="0 0 0" xyz="0 0 -0.025"/>
    </collision>
    <inertial>
      <origin rpy="0 0 0" xyz="0 0 -0.025"/>
      <mass value="1.0"/>
      <inertia ixx="0.002708333333333334" ixy="0" ixz="0" iyy="0.002708333333333334" iyz="0" izz="0.005000000000000001"/>
    </inertial>
  </link>
  <joint name="joint_5" type="continuous">
    <parent link="base_link"/>
    <child link="wheel_left_2"/>
    <axis xyz="0 0 1"/>
    <origin rpy="1.57 0 0" xyz="-0.2 0.2 0.05"/>
  </joint>
  <link name="base_footprint"/>
  <joint name="base_joint" type="fixed">
    <parent link="base_footprint"/>
    <child link="base_link"/>
    <origin rpy="0 0 0" xyz="0 0 0.05"/>
  </joint>
  <gazebo reference="base_link">
    <material>Gazebo/Blue</material>
  </gazebo>
  <gazebo reference="camera">
    <material>Gazebo/Red</material>
    <sensor name="camera_sensor" type="camera">
      <pose>0 0 0 0 0 0</pose>
      <always_on>1</always_on>
      <visualize>true</visualize>
      <update_rate>10.0</update_rate>
      <topic>camera</topic>
    </sensor>
  </gazebo>
  <!--Add lidar sensor-->
  <gazebo reference="lidar">
    <material>Gazebo/White</material>
    <sensor name="lidar" type="ray">
      <pose>0 0 0 0 0 0</pose>
      <visualize>true</visualize>
      <update_rate>40</update_rate>
      <ray>
        <scan>
          <horizontal>
            <samples>360</samples>
            <resolution>1</resolution>
            <min_angle>-3.14</min_angle>
            <max_angle>3.14</max_angle>
          </horizontal>
        </scan>
        <range>
          <min>0.1</min>
          <max>12.0</max>
          <resolution>0.01</resolution>
        </range>
      </ray>
      <plugin filename="libignition-gazebo-sensors-system.so" name="ignition::gazebo::systems::Sensors">
        <ros>
          <!--namespace>/</namespace-->
          <remapping>~/out:=/scan</remapping>
        </ros>
        <!-- Output as a PointCloud2, see above for other types -->
        <output_type>sensor_msgs/LaserScan</output_type>
        <!-- Clip intensity values so all are above 100, optional -->
        <!--min_intensity>100.0</min_intensity-->
        <!-- Frame id for header of output, defaults to sensor's parent link name -->
        <frame_name>lidar</frame_name>
      </plugin>
    </sensor>
  </gazebo>
  <gazebo>
    <plugin filename="libignition-gazebo-diff-drive-system.so" name="ignition::gazebo::systems::DiffDrive">
      <!-- Update rate in Hz -->
      <update_rate>50</update_rate>
      <!--numbers of wheel_pairs-->
      <num_wheel_pairs>2</num_wheel_pairs>
      <!-- wheels -->
      <left_joint>joint_4</left_joint>
      <left_joint>joint_5</left_joint>
      <right_joint>joint_2</right_joint>
      <right_joint>joint_3</right_joint>
      <!-- kinematics -->
      <wheel_separation>0.45</wheel_separation>
      <wheel_diameter>0.1</wheel_diameter>
      <!-- input -->
      <command_topic>cmd_vel</command_topic>
      <!-- output -->
      <odom_publish_frequency>1</odom_publish_frequency>
      <publish_odom>true</publish_odom>
      <publish_odom_tf>true</publish_odom_tf>
      <publish_wheel_tf>true</publish_wheel_tf>
      <odometry_topic>odom</odometry_topic>
      <odometry_frame>odom</odometry_frame>
      <robot_base_frame>base_footprint</robot_base_frame>
    </plugin>
  </gazebo>
</robot>
